<?xml version="1.0"?>
<robot name="tortoisebot" xmlns:xacro="http://www.ros.org/wiki/xacro" >

  <xacro:include filename="$(find tortoisebot_description)/urdf/gazebo_plug_bot.urdf.xacro"/>
  <xacro:load_gazebo_plugin/>

<!-- Base Link -->
  <link name="base_link"/>
  <material name="Gray">
    <color rgba="0.5 0.5 0.5 1.0"/>
  </material>
  <material name="Black">
    <color rgba="0.0 0.0 0.0 1.0"/>
  </material>
  <material name="Red">
    <color rgba="1.0 0.0 0.0 1.0"/>
  </material>
  <material name="Blue">
    <color rgba="0.0 0.0 1.0 1.0"/>
  </material>
  <material name="Green">
    <color rgba="0.0 1.0 0.0 1.0"/>
  </material>
  <material name="White">
    <color rgba="1.0 1.0 1.0 1.0"/>
  </material>
  <!-- Chassis Link -->
  <link name="chassis">
    <inertial>
      <mass value="1.0"/>
      <origin rpy="0 0 0" xyz="0 0 0"/>
      <inertia ixx="0.06083333333333334" ixy="0" ixz="0" iyy="0.1275" iyz="0" izz="0.17333333333333334"/>
    </inertial>
    <visual>
      <origin rpy="0 0 0" xyz="0 0 0"/>
      <geometry>
        <box size="1.2 0.8 0.3"/>
      </geometry>
      <material name="Gray"/>
    </visual>
    <collision>
      <origin rpy="0 0 0" xyz="0 0 0"/>
      <geometry>
        <box size="1.2 0.8 0.3"/>
      </geometry>
    </collision>
  </link>
  <!-- Fixed Joint between base_link and chassis -->
  <joint name="base_to_chassis" type="fixed">
    <parent link="base_link"/>
    <child link="chassis"/>
    <origin rpy="0 0 0" xyz="0 0 0.15"/>
  </joint>
  <link name="left_wheel">
    <inertial>
      <mass value="0.5"/>
      <origin rpy="1.5707963267948966 0 0" xyz="0 0 0"/>
      <inertia ixx="0.00665" ixy="0" ixz="0" iyy="0.00665" iyz="0" izz="0.0121"/>
    </inertial>
    <visual>
      <origin rpy="1.5707963267948966 0 0" xyz="0 0 0"/>
      <geometry>
        <cylinder length="0.12" radius="0.22"/>
      </geometry>
      <material name="Black"/>
    </visual>
    <collision>
      <origin rpy="1.5707963267948966 0 0" xyz="0 0 0"/>
      <geometry>
        <cylinder length="0.12" radius="0.22"/>
      </geometry>
    </collision>
  </link>
  <joint name="left_joint" type="continuous">
    <parent link="chassis"/>
    <child link="left_wheel"/>
    <origin rpy="0 0 0" xyz="-0.3 0.46 -0.15"/>
    <axis xyz="0 1 0"/>
  </joint>
  <link name="right_wheel">
    <inertial>
      <mass value="0.5"/>
      <origin rpy="1.5707963267948966 0 0" xyz="0 0 0"/>
      <inertia ixx="0.00665" ixy="0" ixz="0" iyy="0.00665" iyz="0" izz="0.0121"/>
    </inertial>
    <visual>
      <origin rpy="1.5707963267948966 0 0" xyz="0 0 0"/>
      <geometry>
        <cylinder length="0.12" radius="0.22"/>
      </geometry>
      <material name="Black"/>
    </visual>
    <collision>
      <origin rpy="1.5707963267948966 0 0" xyz="0 0 0"/>
      <geometry>
        <cylinder length="0.12" radius="0.22"/>
      </geometry>
    </collision>
  </link>
  <joint name="right_joint" type="continuous">
    <parent link="chassis"/>
    <child link="right_wheel"/>
    <origin rpy="0 0 0" xyz="-0.3 -0.46 -0.15"/>
    <axis xyz="0 1 0"/>
  </joint>
  <link name="front_caster_wheel">
    <inertial>
      <mass value="0.5"/>
      <origin rpy="0 0 0" xyz="0 0 0"/>
      <inertia ixx="0.00968" ixy="0" ixz="0" iyy="0.00968" iyz="0" izz="0.00968"/>
    </inertial>
    <visual>
      <origin rpy="0 0 0" xyz="0 0 0"/>
      <geometry>
        <sphere radius="0.22"/>
      </geometry>
      <material name="Black"/>
    </visual>
    <collision>
      <origin rpy="0 0 0" xyz="0 0 0"/>
      <geometry>
        <sphere radius="0.22"/>
      </geometry>
    </collision>
  </link>
  <joint name="front_caster_joint" type="continuous">
    <parent link="free-rotating_y_link"/>
    <child link="front_caster_wheel"/>
    <origin rpy="0 0 0" xyz="0 0 0"/>
    <axis xyz="0 0 1"/> 
  </joint>
  <!-- Front free-rotating Link (around y) for 2-Wheeled Robot -->
  <link name="free-rotating_y_link">
    <!-- No mass or geometry needed -->
    <inertial>
      <mass value="0.001"/>
      <!-- Minimal mass to avoid simulation issues -->
      <origin rpy="0 0 0" xyz="0 0 0"/>
      <inertia ixx="1e-6" ixy="0" ixz="0" iyy="1e-6" iyz="0" izz="1e-6"/>
    </inertial>
  </link>
  <joint name="free-rotating_y_joint" type="continuous">
    <parent link="free-rotating_x_link"/>
    <child link="free-rotating_y_link"/>
    <origin rpy="0 0 0" xyz="0 0 0"/>
    <axis xyz="0 1 0"/>
  </joint>
  <!-- Front free-rotating Link (around x) for 2-Wheeled Robot -->
  <link name="free-rotating_x_link">
    <!-- No mass or geometry needed -->
    <inertial>
      <mass value="0.001"/>
      <!-- Minimal mass to avoid simulation issues -->
      <origin rpy="0 0 0" xyz="0 0 0"/>
      <inertia ixx="1e-6" ixy="0" ixz="0" iyy="1e-6" iyz="0" izz="1e-6"/>
    </inertial>
  </link>
  <joint name="free-rotating_x_joint" type="continuous">
    <parent link="chassis"/>
    <child link="free-rotating_x_link"/>
    <origin rpy="0 0 0" xyz="0.38 0 -0.15"/>
    <axis xyz="1 0 0"/>
  </joint>
  
</robot>  
